2021-03-26 06:02:11,238 ERROR: Exception on /index [GET] [in e:\data science\microblog\venv\lib\site-packages\flask\app.py:1891]
Traceback (most recent call last):
  File "e:\data science\microblog\venv\lib\site-packages\flask\app.py", line 2447, in wsgi_app
    response = self.full_dispatch_request()
  File "e:\data science\microblog\venv\lib\site-packages\flask\app.py", line 1952, in full_dispatch_request
    rv = self.handle_user_exception(e)
  File "e:\data science\microblog\venv\lib\site-packages\flask\app.py", line 1821, in handle_user_exception
    reraise(exc_type, exc_value, tb)
  File "e:\data science\microblog\venv\lib\site-packages\flask\_compat.py", line 39, in reraise
    raise value
  File "e:\data science\microblog\venv\lib\site-packages\flask\app.py", line 1950, in full_dispatch_request
    rv = self.dispatch_request()
  File "e:\data science\microblog\venv\lib\site-packages\flask\app.py", line 1936, in dispatch_request
    return self.view_functions[rule.endpoint](**req.view_args)
  File "e:\data science\microblog\venv\lib\site-packages\flask_login\utils.py", line 272, in decorated_view
    return func(*args, **kwargs)
  File "E:\Data Science\microblog\app\routes.py", line 34, in index
    posts = current_user.followed_post().all()
  File "e:\data science\microblog\venv\lib\site-packages\werkzeug\local.py", line 347, in __getattr__
    return getattr(self._get_current_object(), name)
AttributeError: 'User' object has no attribute 'followed_post'
2021-03-26 06:03:49,843 INFO: Microblog startup [in E:\Data Science\microblog\app\__init__.py:45]
2021-03-26 06:03:56,938 ERROR: Exception on / [GET] [in e:\data science\microblog\venv\lib\site-packages\flask\app.py:1891]
Traceback (most recent call last):
  File "e:\data science\microblog\venv\lib\site-packages\flask\app.py", line 2447, in wsgi_app
    response = self.full_dispatch_request()
  File "e:\data science\microblog\venv\lib\site-packages\flask\app.py", line 1952, in full_dispatch_request
    rv = self.handle_user_exception(e)
  File "e:\data science\microblog\venv\lib\site-packages\flask\app.py", line 1821, in handle_user_exception
    reraise(exc_type, exc_value, tb)
  File "e:\data science\microblog\venv\lib\site-packages\flask\_compat.py", line 39, in reraise
    raise value
  File "e:\data science\microblog\venv\lib\site-packages\flask\app.py", line 1950, in full_dispatch_request
    rv = self.dispatch_request()
  File "e:\data science\microblog\venv\lib\site-packages\flask\app.py", line 1936, in dispatch_request
    return self.view_functions[rule.endpoint](**req.view_args)
  File "e:\data science\microblog\venv\lib\site-packages\flask_login\utils.py", line 272, in decorated_view
    return func(*args, **kwargs)
  File "E:\Data Science\microblog\app\routes.py", line 35, in index
    return  render_template('index.html', title = 'Home', posts = posts)
  File "e:\data science\microblog\venv\lib\site-packages\flask\templating.py", line 137, in render_template
    return _render(
  File "e:\data science\microblog\venv\lib\site-packages\flask\templating.py", line 120, in _render
    rv = template.render(context)
  File "e:\data science\microblog\venv\lib\site-packages\jinja2\environment.py", line 1090, in render
    self.environment.handle_exception()
  File "e:\data science\microblog\venv\lib\site-packages\jinja2\environment.py", line 832, in handle_exception
    reraise(*rewrite_traceback_stack(source=source))
  File "e:\data science\microblog\venv\lib\site-packages\jinja2\_compat.py", line 28, in reraise
    raise value.with_traceback(tb)
  File "E:\Data Science\microblog\app\templates\index.html", line 1, in top-level template code
    {% extends "base.html" %}
  File "E:\Data Science\microblog\app\templates\base.html", line 32, in top-level template code
    {% block content %} {% endblock %}
  File "E:\Data Science\microblog\app\templates\index.html", line 6, in block "content"
    {{ form.hidden_tag() }}
  File "e:\data science\microblog\venv\lib\site-packages\jinja2\environment.py", line 471, in getattr
    return getattr(obj, attribute)
jinja2.exceptions.UndefinedError: 'form' is undefined
2021-03-26 06:13:49,529 INFO: Microblog startup [in E:\Data Science\microblog\app\__init__.py:45]
2021-03-26 07:02:16,788 INFO: Microblog startup [in E:\Data Science\microblog\app\__init__.py:45]
2021-03-26 07:09:07,231 INFO: Microblog startup [in E:\Data Science\microblog\app\__init__.py:45]
2021-03-26 07:38:47,951 INFO: Microblog startup [in E:\Data Science\microblog\app\__init__.py:45]
2021-03-26 09:15:16,755 INFO: Microblog startup [in E:\Data Science\microblog\app\__init__.py:45]
2021-03-26 09:16:16,894 ERROR: Exception on /user/mike [GET] [in e:\data science\microblog\venv\lib\site-packages\flask\app.py:1891]
Traceback (most recent call last):
  File "e:\data science\microblog\venv\lib\site-packages\flask\app.py", line 2447, in wsgi_app
    response = self.full_dispatch_request()
  File "e:\data science\microblog\venv\lib\site-packages\flask\app.py", line 1952, in full_dispatch_request
    rv = self.handle_user_exception(e)
  File "e:\data science\microblog\venv\lib\site-packages\flask\app.py", line 1821, in handle_user_exception
    reraise(exc_type, exc_value, tb)
  File "e:\data science\microblog\venv\lib\site-packages\flask\_compat.py", line 39, in reraise
    raise value
  File "e:\data science\microblog\venv\lib\site-packages\flask\app.py", line 1950, in full_dispatch_request
    rv = self.dispatch_request()
  File "e:\data science\microblog\venv\lib\site-packages\flask\app.py", line 1936, in dispatch_request
    return self.view_functions[rule.endpoint](**req.view_args)
  File "e:\data science\microblog\venv\lib\site-packages\flask_login\utils.py", line 272, in decorated_view
    return func(*args, **kwargs)
  File "E:\Data Science\microblog\app\routes.py", line 93, in user
    return render_template('user.html', user=user, posts=posts, form=form, next_url=next_url, prev_url=prev_url)
  File "e:\data science\microblog\venv\lib\site-packages\flask\templating.py", line 137, in render_template
    return _render(
  File "e:\data science\microblog\venv\lib\site-packages\flask\templating.py", line 120, in _render
    rv = template.render(context)
  File "e:\data science\microblog\venv\lib\site-packages\jinja2\environment.py", line 1090, in render
    self.environment.handle_exception()
  File "e:\data science\microblog\venv\lib\site-packages\jinja2\environment.py", line 832, in handle_exception
    reraise(*rewrite_traceback_stack(source=source))
  File "e:\data science\microblog\venv\lib\site-packages\jinja2\_compat.py", line 28, in reraise
    raise value.with_traceback(tb)
  File "E:\Data Science\microblog\app\templates\user.html", line 1, in top-level template code
    {% extends "base.html" %}
  File "E:\Data Science\microblog\app\templates\base.html", line 33, in top-level template code
    {% block content %} {% endblock %}
  File "E:\Data Science\microblog\app\templates\user.html", line 40, in block "content"
    {% for post in posts %}
TypeError: 'Pagination' object is not iterable
2021-03-26 09:28:19,881 INFO: Microblog startup [in E:\Data Science\microblog\app\__init__.py:45]
