2021-03-28 12:35:54,187 ERROR: Exception on /reset_password_request [POST] [in e:\data science\microblog\venv\lib\site-packages\flask\app.py:1891]
Traceback (most recent call last):
  File "e:\data science\microblog\venv\lib\site-packages\flask\app.py", line 2447, in wsgi_app
    response = self.full_dispatch_request()
  File "e:\data science\microblog\venv\lib\site-packages\flask\app.py", line 1952, in full_dispatch_request
    rv = self.handle_user_exception(e)
  File "e:\data science\microblog\venv\lib\site-packages\flask\app.py", line 1821, in handle_user_exception
    reraise(exc_type, exc_value, tb)
  File "e:\data science\microblog\venv\lib\site-packages\flask\_compat.py", line 39, in reraise
    raise value
  File "e:\data science\microblog\venv\lib\site-packages\flask\app.py", line 1950, in full_dispatch_request
    rv = self.dispatch_request()
  File "e:\data science\microblog\venv\lib\site-packages\flask\app.py", line 1936, in dispatch_request
    return self.view_functions[rule.endpoint](**req.view_args)
  File "E:\Data Science\microblog\app\routes.py", line 171, in reset_password_request
    user = User.query.filter_by(email=form.data.email).first()
AttributeError: 'dict' object has no attribute 'email'
2021-03-28 12:38:11,314 INFO: Microblog startup [in E:\Data Science\microblog\app\__init__.py:46]
2021-03-28 12:38:23,958 ERROR: Exception on /reset_password_request [POST] [in e:\data science\microblog\venv\lib\site-packages\flask\app.py:1891]
Traceback (most recent call last):
  File "e:\data science\microblog\venv\lib\site-packages\flask\app.py", line 2447, in wsgi_app
    response = self.full_dispatch_request()
  File "e:\data science\microblog\venv\lib\site-packages\flask\app.py", line 1952, in full_dispatch_request
    rv = self.handle_user_exception(e)
  File "e:\data science\microblog\venv\lib\site-packages\flask\app.py", line 1821, in handle_user_exception
    reraise(exc_type, exc_value, tb)
  File "e:\data science\microblog\venv\lib\site-packages\flask\_compat.py", line 39, in reraise
    raise value
  File "e:\data science\microblog\venv\lib\site-packages\flask\app.py", line 1950, in full_dispatch_request
    rv = self.dispatch_request()
  File "e:\data science\microblog\venv\lib\site-packages\flask\app.py", line 1936, in dispatch_request
    return self.view_functions[rule.endpoint](**req.view_args)
  File "E:\Data Science\microblog\app\routes.py", line 173, in reset_password_request
    send_password_reset_email(user)
  File "E:\Data Science\microblog\app\email.py", line 13, in send_password_reset_email
    token = user.get_password_reset_token()
AttributeError: 'User' object has no attribute 'get_password_reset_token'
2021-03-28 12:47:46,417 INFO: Microblog startup [in E:\Data Science\microblog\app\__init__.py:46]
2021-03-28 12:48:26,274 ERROR: Exception on /reset_password_request [POST] [in e:\data science\microblog\venv\lib\site-packages\flask\app.py:1891]
Traceback (most recent call last):
  File "e:\data science\microblog\venv\lib\site-packages\flask\app.py", line 2447, in wsgi_app
    response = self.full_dispatch_request()
  File "e:\data science\microblog\venv\lib\site-packages\flask\app.py", line 1952, in full_dispatch_request
    rv = self.handle_user_exception(e)
  File "e:\data science\microblog\venv\lib\site-packages\flask\app.py", line 1821, in handle_user_exception
    reraise(exc_type, exc_value, tb)
  File "e:\data science\microblog\venv\lib\site-packages\flask\_compat.py", line 39, in reraise
    raise value
  File "e:\data science\microblog\venv\lib\site-packages\flask\app.py", line 1950, in full_dispatch_request
    rv = self.dispatch_request()
  File "e:\data science\microblog\venv\lib\site-packages\flask\app.py", line 1936, in dispatch_request
    return self.view_functions[rule.endpoint](**req.view_args)
  File "E:\Data Science\microblog\app\routes.py", line 173, in reset_password_request
    send_password_reset_email(user)
  File "E:\Data Science\microblog\app\email.py", line 13, in send_password_reset_email
    token = user.get_reset_password_token()
  File "E:\Data Science\microblog\app\models.py", line 64, in get_reset_password_token
    return jwt.encode(
TypeError: encode() got an unexpected keyword argument 'algorithms'
2021-03-28 12:49:52,473 INFO: Microblog startup [in E:\Data Science\microblog\app\__init__.py:46]
2021-03-28 12:50:20,288 ERROR: Exception on /reset_password_request [POST] [in e:\data science\microblog\venv\lib\site-packages\flask\app.py:1891]
Traceback (most recent call last):
  File "e:\data science\microblog\venv\lib\site-packages\flask_mail.py", line 492, in send
    message.send(connection)
  File "e:\data science\microblog\venv\lib\site-packages\flask_mail.py", line 427, in send
    connection.send(self)
  File "e:\data science\microblog\venv\lib\site-packages\flask_mail.py", line 188, in send
    self.host.sendmail(sanitize_address(envelope_from or message.sender),
  File "C:\Users\Maharaj\AppData\Local\Programs\Python\Python38\lib\smtplib.py", line 856, in sendmail
    self.ehlo_or_helo_if_needed()
  File "C:\Users\Maharaj\AppData\Local\Programs\Python\Python38\lib\smtplib.py", line 604, in ehlo_or_helo_if_needed
    if not (200 <= self.ehlo()[0] <= 299):
  File "C:\Users\Maharaj\AppData\Local\Programs\Python\Python38\lib\smtplib.py", line 444, in ehlo
    self.putcmd(self.ehlo_msg, name or self.local_hostname)
  File "C:\Users\Maharaj\AppData\Local\Programs\Python\Python38\lib\smtplib.py", line 371, in putcmd
    self.send(str)
  File "C:\Users\Maharaj\AppData\Local\Programs\Python\Python38\lib\smtplib.py", line 363, in send
    raise SMTPServerDisconnected('please run connect() first')
smtplib.SMTPServerDisconnected: please run connect() first

During handling of the above exception, another exception occurred:

Traceback (most recent call last):
  File "e:\data science\microblog\venv\lib\site-packages\flask\app.py", line 2447, in wsgi_app
    response = self.full_dispatch_request()
  File "e:\data science\microblog\venv\lib\site-packages\flask\app.py", line 1952, in full_dispatch_request
    rv = self.handle_user_exception(e)
  File "e:\data science\microblog\venv\lib\site-packages\flask\app.py", line 1821, in handle_user_exception
    reraise(exc_type, exc_value, tb)
  File "e:\data science\microblog\venv\lib\site-packages\flask\_compat.py", line 39, in reraise
    raise value
  File "e:\data science\microblog\venv\lib\site-packages\flask\app.py", line 1950, in full_dispatch_request
    rv = self.dispatch_request()
  File "e:\data science\microblog\venv\lib\site-packages\flask\app.py", line 1936, in dispatch_request
    return self.view_functions[rule.endpoint](**req.view_args)
  File "E:\Data Science\microblog\app\routes.py", line 173, in reset_password_request
    send_password_reset_email(user)
  File "E:\Data Science\microblog\app\email.py", line 14, in send_password_reset_email
    send_email('[Microblog] Reset Your Password',
  File "E:\Data Science\microblog\app\email.py", line 10, in send_email
    mail.send(msg)
  File "e:\data science\microblog\venv\lib\site-packages\flask_mail.py", line 492, in send
    message.send(connection)
  File "e:\data science\microblog\venv\lib\site-packages\flask_mail.py", line 152, in __exit__
    self.host.quit()
  File "C:\Users\Maharaj\AppData\Local\Programs\Python\Python38\lib\smtplib.py", line 988, in quit
    res = self.docmd("quit")
  File "C:\Users\Maharaj\AppData\Local\Programs\Python\Python38\lib\smtplib.py", line 424, in docmd
    self.putcmd(cmd, args)
  File "C:\Users\Maharaj\AppData\Local\Programs\Python\Python38\lib\smtplib.py", line 371, in putcmd
    self.send(str)
  File "C:\Users\Maharaj\AppData\Local\Programs\Python\Python38\lib\smtplib.py", line 363, in send
    raise SMTPServerDisconnected('please run connect() first')
smtplib.SMTPServerDisconnected: please run connect() first
2021-03-28 12:52:00,882 INFO: Microblog startup [in E:\Data Science\microblog\app\__init__.py:46]
2021-03-29 09:57:55,697 INFO: Microblog startup [in E:\Data Science\microblog\app\__init__.py:46]
2021-03-29 10:08:14,755 INFO: Microblog startup [in E:\Data Science\microblog\app\__init__.py:46]
2021-03-30 04:39:11,185 INFO: Microblog startup [in E:\Data Science\microblog\app\__init__.py:46]
2021-03-30 04:46:11,145 INFO: Microblog startup [in E:\Data Science\microblog\app\__init__.py:46]
2021-03-30 04:54:38,697 INFO: Microblog startup [in E:\Data Science\microblog\app\__init__.py:46]
2021-03-30 05:09:13,090 INFO: Microblog startup [in E:\Data Science\microblog\app\__init__.py:46]
2021-03-30 05:21:41,028 INFO: Microblog startup [in E:\Data Science\microblog\app\__init__.py:46]
2021-03-30 05:48:07,334 INFO: Microblog startup [in E:\Data Science\microblog\app\__init__.py:46]
2021-03-30 06:03:37,679 INFO: Microblog startup [in E:\Data Science\microblog\app\__init__.py:46]
2021-03-30 06:05:26,425 INFO: Microblog startup [in E:\Data Science\microblog\app\__init__.py:46]
2021-03-30 06:12:05,628 INFO: Microblog startup [in E:\Data Science\microblog\app\__init__.py:46]
2021-03-30 06:17:34,307 INFO: Microblog startup [in E:\Data Science\microblog\app\__init__.py:46]
2021-03-30 06:19:01,662 INFO: Microblog startup [in E:\Data Science\microblog\app\__init__.py:46]
2021-03-30 06:23:04,791 INFO: Microblog startup [in E:\Data Science\microblog\app\__init__.py:46]
2021-03-30 06:28:12,266 INFO: Microblog startup [in E:\Data Science\microblog\app\__init__.py:46]
2021-03-30 06:31:23,647 INFO: Microblog startup [in E:\Data Science\microblog\app\__init__.py:46]
2021-03-30 06:34:21,741 INFO: Microblog startup [in E:\Data Science\microblog\app\__init__.py:46]
2021-03-30 06:36:05,057 INFO: Microblog startup [in E:\Data Science\microblog\app\__init__.py:46]
2021-03-30 06:37:47,381 INFO: Microblog startup [in E:\Data Science\microblog\app\__init__.py:46]
2021-03-30 06:40:47,468 INFO: Microblog startup [in E:\Data Science\microblog\app\__init__.py:46]
2021-03-30 06:43:23,511 INFO: Microblog startup [in E:\Data Science\microblog\app\__init__.py:46]
